Traceback (most recent call last):
  File "C:\Users\alber\anaconda3\envs\ambiente_1\Lib\site-packages\jupyter_cache\executors\utils.py", line 58, in single_nb_execution
    executenb(
  File "C:\Users\alber\anaconda3\envs\ambiente_1\Lib\site-packages\nbclient\client.py", line 1305, in execute
    return NotebookClient(nb=nb, resources=resources, km=km, **kwargs).execute()
           ^^^^^^^^^^^^^^^^^^^^^^^^^^^^^^^^^^^^^^^^^^^^^^^^^^^^^^^^^^^^^^^^^^^^^
  File "C:\Users\alber\anaconda3\envs\ambiente_1\Lib\site-packages\jupyter_core\utils\__init__.py", line 165, in wrapped
    return loop.run_until_complete(inner)
           ^^^^^^^^^^^^^^^^^^^^^^^^^^^^^^
  File "C:\Users\alber\anaconda3\envs\ambiente_1\Lib\asyncio\base_events.py", line 686, in run_until_complete
    return future.result()
           ^^^^^^^^^^^^^^^
  File "C:\Users\alber\anaconda3\envs\ambiente_1\Lib\site-packages\nbclient\client.py", line 705, in async_execute
    await self.async_execute_cell(
  File "C:\Users\alber\anaconda3\envs\ambiente_1\Lib\site-packages\nbclient\client.py", line 1058, in async_execute_cell
    await self._check_raise_for_error(cell, cell_index, exec_reply)
  File "C:\Users\alber\anaconda3\envs\ambiente_1\Lib\site-packages\nbclient\client.py", line 914, in _check_raise_for_error
    raise CellExecutionError.from_cell_and_msg(cell, exec_reply_content)
nbclient.exceptions.CellExecutionError: An error occurred while executing the following cell:
------------------
# + tags=["remove-input"]
df[['Defectos']].plot.box(
    title='Distribuci√≥n de defectos en el mes',
    figsize=(6, 5),
    grid=True,
    color=dict(boxes='blue', whiskers='black', medians='red', caps='green')
)

------------------


[1;31m---------------------------------------------------------------------------[0m
[1;31mNameError[0m                                 Traceback (most recent call last)
Cell [1;32mIn[1], line 2[0m
[0;32m      1[0m [38;5;66;03m# + tags=["remove-input"][39;00m
[1;32m----> 2[0m df[[[38;5;124m'[39m[38;5;124mDefectos[39m[38;5;124m'[39m]][38;5;241m.[39mplot[38;5;241m.[39mbox(
[0;32m      3[0m     title[38;5;241m=[39m[38;5;124m'[39m[38;5;124mDistribuci√≥n de defectos en el mes[39m[38;5;124m'[39m,
[0;32m      4[0m     figsize[38;5;241m=[39m([38;5;241m6[39m, [38;5;241m5[39m),
[0;32m      5[0m     grid[38;5;241m=[39m[38;5;28;01mTrue[39;00m,
[0;32m      6[0m     color[38;5;241m=[39m[38;5;28mdict[39m(boxes[38;5;241m=[39m[38;5;124m'[39m[38;5;124mblue[39m[38;5;124m'[39m, whiskers[38;5;241m=[39m[38;5;124m'[39m[38;5;124mblack[39m[38;5;124m'[39m, medians[38;5;241m=[39m[38;5;124m'[39m[38;5;124mred[39m[38;5;124m'[39m, caps[38;5;241m=[39m[38;5;124m'[39m[38;5;124mgreen[39m[38;5;124m'[39m)
[0;32m      7[0m )

[1;31mNameError[0m: name 'df' is not defined

